Workbook

Sheet real draft
A1: Player | B1: FG% | C1: FT% | D1: 3PM | E1: PTS | F1: TREB | G1: AST | H1: STL | I1: BLK | J1: TO | L1: Rds1-2 | M1: MyRAnk | N1: LY Rank | O1: FG% | P1: FT% | Q1: 3PM | R1: PTS | S1: TREB | T1: AST | U1: STL | V1: BLK | W1: TO
A2: Nikola Jokic | B2: =VLOOKUP($A2,'2026-2027 projections'!$B:$AJ,23,FALSE) -> 3.0692222 | C2: =VLOOKUP($A2,'2026-2027 projections'!$B:$AJ,24,FALSE) -> 0.67648884 | D2: =VLOOKUP($A2,'2026-2027 projections'!$B:$AJ,25,FALSE) -> 0.13976398 | E2: =VLOOKUP($A2,'2026-2027 projections'!$B:$AJ,26,FALSE) -> 2.3666915 | F2: =VLOOKUP($A2,'2026-2027 projections'!$B:$AJ,27,FALSE) -> 2.9186971 | G2: =VLOOKUP($A2,'2026-2027 projections'!$B:$AJ,28,FALSE) -> 3.4855537 | H2: =VLOOKUP($A2,'2026-2027 projections'!$B:$AJ,29,FALSE) -> 1.7128721 | I2: =VLOOKUP($A2,'2026-2027 projections'!$B:$AJ,30,FALSE) -> 0.043434608 | J2: =VLOOKUP($A2,'2026-2027 projections'!$B:$AJ,31,FALSE) -> -2 | L2: Nikola Jokic | M2: =VLOOKUP(L2,'2026-2027 projections'!B:C,2,FALSE) -> 1 | N2: =VLOOKUP(L2,'2026-2027 projections'!B:D,3,FALSE) -> 1 | O2: =VLOOKUP($L2,'2026-2027 projections'!$B:$AJ,23,FALSE) -> 3.0692222 | P2: =VLOOKUP($L2,'2026-2027 projections'!$B:$AJ,24,FALSE) -> 0.67648884 | Q2: =VLOOKUP($L2,'2026-2027 projections'!$B:$AJ,25,FALSE) -> 0.13976398 | R2: =VLOOKUP($L2,'2026-2027 projections'!$B:$AJ,26,FALSE) -> 2.3666915 | S2: =VLOOKUP($L2,'2026-2027 projections'!$B:$AJ,27,FALSE) -> 2.9186971 | T2: =VLOOKUP($L2,'2026-2027 projections'!$B:$AJ,28,FALSE) -> 3.4855537 | U2: =VLOOKUP($L2,'2026-2027 projections'!$B:$AJ,29,FALSE) -> 1.7128721 | V2: =VLOOKUP($L2,'2026-2027 projections'!$B:$AJ,30,FALSE) -> 0.043434608 | W2: =VLOOKUP($L2,'2026-2027 projections'!$B:$AJ,31,FALSE) -> -2 | AC2: FG% | AD2: FT% | AE2: 3PM | AF2: PTS | AG2: Reb | AH2: AST | AI2: STL | AJ2: BLK | AK2: TO
A3: Tyrese Haliburton | B3: =VLOOKUP($A3,'2026-2027 projections'!$B:$AJ,23,FALSE) -> -0.32171307 | C3: =VLOOKUP($A3,'2026-2027 projections'!$B:$AJ,24,FALSE) -> 0.60575292 | D3: =VLOOKUP($A3,'2026-2027 projections'!$B:$AJ,25,FALSE) -> 1.1919198 | E3: =VLOOKUP($A3,'2026-2027 projections'!$B:$AJ,26,FALSE) -> 0.2655712 | F3: =VLOOKUP($A3,'2026-2027 projections'!$B:$AJ,27,FALSE) -> -0.99291185 | G3: =VLOOKUP($A3,'2026-2027 projections'!$B:$AJ,28,FALSE) -> 3.0724967 | H3: =VLOOKUP($A3,'2026-2027 projections'!$B:$AJ,29,FALSE) -> 0.83234193 | I3: =VLOOKUP($A3,'2026-2027 projections'!$B:$AJ,30,FALSE) -> -0.15959693 | J3: =VLOOKUP($A3,'2026-2027 projections'!$B:$AJ,31,FALSE) -> 0.19892375 | L3: Tyrese Haliburton | M3: =VLOOKUP(L3,'2026-2027 projections'!B:C,2,FALSE) -> 8 | N3: =VLOOKUP(L3,'2026-2027 projections'!B:D,3,FALSE) -> #N/A | O3: =VLOOKUP($L3,'2026-2027 projections'!$B:$AJ,23,FALSE) -> -0.32171307 | P3: =VLOOKUP($L3,'2026-2027 projections'!$B:$AJ,24,FALSE) -> 0.60575292 | Q3: =VLOOKUP($L3,'2026-2027 projections'!$B:$AJ,25,FALSE) -> 1.1919198 | R3: =VLOOKUP($L3,'2026-2027 projections'!$B:$AJ,26,FALSE) -> 0.2655712 | S3: =VLOOKUP($L3,'2026-2027 projections'!$B:$AJ,27,FALSE) -> -0.99291185 | T3: =VLOOKUP($L3,'2026-2027 projections'!$B:$AJ,28,FALSE) -> 3.0724967 | U3: =VLOOKUP($L3,'2026-2027 projections'!$B:$AJ,29,FALSE) -> 0.83234193 | V3: =VLOOKUP($L3,'2026-2027 projections'!$B:$AJ,30,FALSE) -> -0.15959693 | W3: =VLOOKUP($L3,'2026-2027 projections'!$B:$AJ,31,FALSE) -> 0.19892375 | AA3: Team avg | AC3: =SUM(#REF!)/SUM(#REF!) -> #REF! | AD3: =SUM(#REF!)/SUM(#REF!) -> #REF! | AE3: =AVERAGE(#REF!) -> #REF! | AF3: =AVERAGE(#REF!) -> #REF! | AG3: =AVERAGE(#REF!) -> #REF! | AH3: =AVERAGE(#REF!) -> #REF! | AI3: =AVERAGE(#REF!) -> #REF! | AJ3: =AVERAGE(#REF!) -> #REF! | AK3: =AVERAGE(#REF!) -> #REF!
B4: =VLOOKUP($A4,'2026-2027 projections'!$B:$AJ,23,FALSE) -> #N/A | C4: =VLOOKUP($A4,'2026-2027 projections'!$B:$AJ,24,FALSE) -> #N/A | D4: =VLOOKUP($A4,'2026-2027 projections'!$B:$AJ,25,FALSE) -> #N/A | E4: =VLOOKUP($A4,'2026-2027 projections'!$B:$AJ,26,FALSE) -> #N/A | F4: =VLOOKUP($A4,'2026-2027 projections'!$B:$AJ,27,FALSE) -> #N/A | G4: =VLOOKUP($A4,'2026-2027 projections'!$B:$AJ,28,FALSE) -> #N/A | H4: =VLOOKUP($A4,'2026-2027 projections'!$B:$AJ,29,FALSE) -> #N/A | I4: =VLOOKUP($A4,'2026-2027 projections'!$B:$AJ,30,FALSE) -> #N/A | J4: =VLOOKUP($A4,'2026-2027 projections'!$B:$AJ,31,FALSE) -> #N/A | L4: Jayson Tatum | M4: =VLOOKUP(L4,'2026-2027 projections'!B:C,2,FALSE) -> 7 | N4: =VLOOKUP(L4,'2026-2027 projections'!B:D,3,FALSE) -> 30 | O4: =VLOOKUP($L4,'2026-2027 projections'!$B:$AJ,23,FALSE) -> -0.66986601 | P4: =VLOOKUP($L4,'2026-2027 projections'!$B:$AJ,24,FALSE) -> 0.65880486 | Q4: =VLOOKUP($L4,'2026-2027 projections'!$B:$AJ,25,FALSE) -> 1.7179977 | R4: =VLOOKUP($L4,'2026-2027 projections'!$B:$AJ,26,FALSE) -> 1.9313242 | S4: =VLOOKUP($L4,'2026-2027 projections'!$B:$AJ,27,FALSE) -> 1.2957955 | T4: =VLOOKUP($L4,'2026-2027 projections'!$B:$AJ,28,FALSE) -> 1.2653723 | U4: =VLOOKUP($L4,'2026-2027 projections'!$B:$AJ,29,FALSE) -> 0.53883188 | V4: =VLOOKUP($L4,'2026-2027 projections'!$B:$AJ,30,FALSE) -> -0.36262847 | W4: =VLOOKUP($L4,'2026-2027 projections'!$B:$AJ,31,FALSE) -> -1.3021698 | AA4: Pop Means | AC4: 0.48 | AD4: 0.795 | AE4: 1.71 | AF4: 16 | AG4: 5.6 | AH4: 3.5 | AI4: 1 | AJ4: =#REF! -> #REF! | AK4: =#REF! -> #REF!
B5: =VLOOKUP($A5,'2026-2027 projections'!$B:$AJ,23,FALSE) -> #N/A | C5: =VLOOKUP($A5,'2026-2027 projections'!$B:$AJ,24,FALSE) -> #N/A | D5: =VLOOKUP($A5,'2026-2027 projections'!$B:$AJ,25,FALSE) -> #N/A | E5: =VLOOKUP($A5,'2026-2027 projections'!$B:$AJ,26,FALSE) -> #N/A | F5: =VLOOKUP($A5,'2026-2027 projections'!$B:$AJ,27,FALSE) -> #N/A | G5: =VLOOKUP($A5,'2026-2027 projections'!$B:$AJ,28,FALSE) -> #N/A | H5: =VLOOKUP($A5,'2026-2027 projections'!$B:$AJ,29,FALSE) -> #N/A | I5: =VLOOKUP($A5,'2026-2027 projections'!$B:$AJ,30,FALSE) -> #N/A | J5: =VLOOKUP($A5,'2026-2027 projections'!$B:$AJ,31,FALSE) -> #N/A | L5: Anthony Edwards | M5: =VLOOKUP(L5,'2026-2027 projections'!B:C,2,FALSE) -> 13 | N5: =VLOOKUP(L5,'2026-2027 projections'!B:D,3,FALSE) -> 15 | O5: =VLOOKUP($L5,'2026-2027 projections'!$B:$AJ,23,FALSE) -> 0.085699774 | P5: =VLOOKUP($L5,'2026-2027 projections'!$B:$AJ,24,FALSE) -> 0.5338926 | Q5: =VLOOKUP($L5,'2026-2027 projections'!$B:$AJ,25,FALSE) -> 2.13886 | R5: =VLOOKUP($L5,'2026-2027 projections'!$B:$AJ,26,FALSE) -> 2.4234785 | S5: =VLOOKUP($L5,'2026-2027 projections'!$B:$AJ,27,FALSE) -> -0.035816045 | T5: =VLOOKUP($L5,'2026-2027 projections'!$B:$AJ,28,FALSE) -> -0.077062871 | U5: =VLOOKUP($L5,'2026-2027 projections'!$B:$AJ,29,FALSE) -> 0.53883188 | V5: =VLOOKUP($L5,'2026-2027 projections'!$B:$AJ,30,FALSE) -> 0.043434608 | W5: =VLOOKUP($L5,'2026-2027 projections'!$B:$AJ,31,FALSE) -> -1.5750959
B6: =VLOOKUP($A6,'2026-2027 projections'!$B:$AJ,23,FALSE) -> #N/A | C6: =VLOOKUP($A6,'2026-2027 projections'!$B:$AJ,24,FALSE) -> #N/A | D6: =VLOOKUP($A6,'2026-2027 projections'!$B:$AJ,25,FALSE) -> #N/A | E6: =VLOOKUP($A6,'2026-2027 projections'!$B:$AJ,26,FALSE) -> #N/A | F6: =VLOOKUP($A6,'2026-2027 projections'!$B:$AJ,27,FALSE) -> #N/A | G6: =VLOOKUP($A6,'2026-2027 projections'!$B:$AJ,28,FALSE) -> #N/A | H6: =VLOOKUP($A6,'2026-2027 projections'!$B:$AJ,29,FALSE) -> #N/A | I6: =VLOOKUP($A6,'2026-2027 projections'!$B:$AJ,30,FALSE) -> #N/A | J6: =VLOOKUP($A6,'2026-2027 projections'!$B:$AJ,31,FALSE) -> #N/A | L6: Donovan Mitchell | M6: =VLOOKUP(L6,'2026-2027 projections'!B:C,2,FALSE) -> 11 | N6: =VLOOKUP(L6,'2026-2027 projections'!B:D,3,FALSE) -> 7 | O6: =VLOOKUP($L6,'2026-2027 projections'!$B:$AJ,23,FALSE) -> -0.73958851 | P6: =VLOOKUP($L6,'2026-2027 projections'!$B:$AJ,24,FALSE) -> 1.0064535 | Q6: =VLOOKUP($L6,'2026-2027 projections'!$B:$AJ,25,FALSE) -> 1.7179977 | R6: =VLOOKUP($L6,'2026-2027 projections'!$B:$AJ,26,FALSE) -> 2.0827563 | S6: =VLOOKUP($L6,'2026-2027 projections'!$B:$AJ,27,FALSE) -> -0.4103318 | T6: =VLOOKUP($L6,'2026-2027 projections'!$B:$AJ,28,FALSE) -> 0.90394748 | U6: =VLOOKUP($L6,'2026-2027 projections'!$B:$AJ,29,FALSE) -> 1.419362 | V6: =VLOOKUP($L6,'2026-2027 projections'!$B:$AJ,30,FALSE) -> -0.76869155 | W6: =VLOOKUP($L6,'2026-2027 projections'!$B:$AJ,31,FALSE) -> -1.0292437 | AA6: Stdev to pop | AC6: =((SUM(#REF!)/SUM(#REF!))-#REF!)/#REF!*SQRT(SUM(#REF!)/(COUNT(#REF!)*#REF!)) -> #REF! | AD6: =IFERROR(((SUM(#REF!)/SUM(#REF!)-#REF!)/#REF!)*SQRT(SUM(#REF!)/(COUNT(#REF!)*#REF!)),"n/a") -> n/a | AE6: =(AVERAGE(#REF!)-#REF!)/#REF! -> #REF! | AF6: =(AVERAGE(#REF!)-#REF!)/#REF! -> #REF! | AG6: =(AVERAGE(#REF!)-#REF!)/#REF! -> #REF! | AH6: =(AVERAGE(#REF!)-#REF!)/#REF! -> #REF! | AI6: =(AVERAGE(#REF!)-#REF!)/#REF! -> #REF! | AJ6: =(AVERAGE(#REF!)-#REF!)/#REF! -> #REF! | AK6: =(AVERAGE(#REF!)-#REF!)/#REF!*-1 -> #REF!
B7: =VLOOKUP($A7,'2026-2027 projections'!$B:$AJ,23,FALSE) -> #N/A | C7: =VLOOKUP($A7,'2026-2027 projections'!$B:$AJ,24,FALSE) -> #N/A | D7: =VLOOKUP($A7,'2026-2027 projections'!$B:$AJ,25,FALSE) -> #N/A | E7: =VLOOKUP($A7,'2026-2027 projections'!$B:$AJ,26,FALSE) -> #N/A | F7: =VLOOKUP($A7,'2026-2027 projections'!$B:$AJ,27,FALSE) -> #N/A | G7: =VLOOKUP($A7,'2026-2027 projections'!$B:$AJ,28,FALSE) -> #N/A | H7: =VLOOKUP($A7,'2026-2027 projections'!$B:$AJ,29,FALSE) -> #N/A | I7: =VLOOKUP($A7,'2026-2027 projections'!$B:$AJ,30,FALSE) -> #N/A | J7: =VLOOKUP($A7,'2026-2027 projections'!$B:$AJ,31,FALSE) -> #N/A | M7: =VLOOKUP(L7,'2026-2027 projections'!B:C,2,FALSE) -> #N/A | N7: =VLOOKUP(L7,'2026-2027 projections'!B:D,3,FALSE) -> #N/A | O7: =VLOOKUP($L7,'2026-2027 projections'!$B:$AJ,23,FALSE) -> #N/A | P7: =VLOOKUP($L7,'2026-2027 projections'!$B:$AJ,24,FALSE) -> #N/A | Q7: =VLOOKUP($L7,'2026-2027 projections'!$B:$AJ,25,FALSE) -> #N/A | R7: =VLOOKUP($L7,'2026-2027 projections'!$B:$AJ,26,FALSE) -> #N/A | S7: =VLOOKUP($L7,'2026-2027 projections'!$B:$AJ,27,FALSE) -> #N/A | T7: =VLOOKUP($L7,'2026-2027 projections'!$B:$AJ,28,FALSE) -> #N/A | U7: =VLOOKUP($L7,'2026-2027 projections'!$B:$AJ,29,FALSE) -> #N/A | V7: =VLOOKUP($L7,'2026-2027 projections'!$B:$AJ,30,FALSE) -> #N/A | W7: =VLOOKUP($L7,'2026-2027 projections'!$B:$AJ,31,FALSE) -> #N/A
B8: =VLOOKUP($A8,'2026-2027 projections'!$B:$AJ,23,FALSE) -> #N/A | C8: =VLOOKUP($A8,'2026-2027 projections'!$B:$AJ,24,FALSE) -> #N/A | D8: =VLOOKUP($A8,'2026-2027 projections'!$B:$AJ,25,FALSE) -> #N/A | E8: =VLOOKUP($A8,'2026-2027 projections'!$B:$AJ,26,FALSE) -> #N/A | F8: =VLOOKUP($A8,'2026-2027 projections'!$B:$AJ,27,FALSE) -> #N/A | G8: =VLOOKUP($A8,'2026-2027 projections'!$B:$AJ,28,FALSE) -> #N/A | H8: =VLOOKUP($A8,'2026-2027 projections'!$B:$AJ,29,FALSE) -> #N/A | I8: =VLOOKUP($A8,'2026-2027 projections'!$B:$AJ,30,FALSE) -> #N/A | J8: =VLOOKUP($A8,'2026-2027 projections'!$B:$AJ,31,FALSE) -> #N/A | M8: =VLOOKUP(L8,'2026-2027 projections'!B:C,2,FALSE) -> #N/A | N8: =VLOOKUP(L8,'2026-2027 projections'!B:D,3,FALSE) -> #N/A | O8: =VLOOKUP($L8,'2026-2027 projections'!$B:$AJ,23,FALSE) -> #N/A | P8: =VLOOKUP($L8,'2026-2027 projections'!$B:$AJ,24,FALSE) -> #N/A | Q8: =VLOOKUP($L8,'2026-2027 projections'!$B:$AJ,25,FALSE) -> #N/A | R8: =VLOOKUP($L8,'2026-2027 projections'!$B:$AJ,26,FALSE) -> #N/A | S8: =VLOOKUP($L8,'2026-2027 projections'!$B:$AJ,27,FALSE) -> #N/A | T8: =VLOOKUP($L8,'2026-2027 projections'!$B:$AJ,28,FALSE) -> #N/A | U8: =VLOOKUP($L8,'2026-2027 projections'!$B:$AJ,29,FALSE) -> #N/A | V8: =VLOOKUP($L8,'2026-2027 projections'!$B:$AJ,30,FALSE) -> #N/A | W8: =VLOOKUP($L8,'2026-2027 projections'!$B:$AJ,31,FALSE) -> #N/A
B9: =VLOOKUP($A9,'2026-2027 projections'!$B:$AJ,23,FALSE) -> #N/A | C9: =VLOOKUP($A9,'2026-2027 projections'!$B:$AJ,24,FALSE) -> #N/A | D9: =VLOOKUP($A9,'2026-2027 projections'!$B:$AJ,25,FALSE) -> #N/A | E9: =VLOOKUP($A9,'2026-2027 projections'!$B:$AJ,26,FALSE) -> #N/A | F9: =VLOOKUP($A9,'2026-2027 projections'!$B:$AJ,27,FALSE) -> #N/A | G9: =VLOOKUP($A9,'2026-2027 projections'!$B:$AJ,28,FALSE) -> #N/A | H9: =VLOOKUP($A9,'2026-2027 projections'!$B:$AJ,29,FALSE) -> #N/A | I9: =VLOOKUP($A9,'2026-2027 projections'!$B:$AJ,30,FALSE) -> #N/A | J9: =VLOOKUP($A9,'2026-2027 projections'!$B:$AJ,31,FALSE) -> #N/A | M9: =VLOOKUP(L9,#REF!,2,FALSE) -> #REF! | N9: =VLOOKUP(L9,#REF!,3,FALSE) -> #REF! | O9: =VLOOKUP($L9,'2026-2027 projections'!$B:$AJ,23,FALSE) -> #N/A | P9: =VLOOKUP($L9,'2026-2027 projections'!$B:$AJ,24,FALSE) -> #N/A | Q9: =VLOOKUP($L9,'2026-2027 projections'!$B:$AJ,25,FALSE) -> #N/A | R9: =VLOOKUP($L9,'2026-2027 projections'!$B:$AJ,26,FALSE) -> #N/A | S9: =VLOOKUP($L9,'2026-2027 projections'!$B:$AJ,27,FALSE) -> #N/A | T9: =VLOOKUP($L9,'2026-2027 projections'!$B:$AJ,28,FALSE) -> #N/A | U9: =VLOOKUP($L9,'2026-2027 projections'!$B:$AJ,29,FALSE) -> #N/A | V9: =VLOOKUP($L9,'2026-2027 projections'!$B:$AJ,30,FALSE) -> #N/A | W9: =VLOOKUP($L9,'2026-2027 projections'!$B:$AJ,31,FALSE) -> #N/A | AB9: what does adding this player do to my existing roster's stats?
B10: =VLOOKUP($A10,'2026-2027 projections'!$B:$AJ,23,FALSE) -> #N/A | C10: =VLOOKUP($A10,'2026-2027 projections'!$B:$AJ,24,FALSE) -> #N/A | D10: =VLOOKUP($A10,'2026-2027 projections'!$B:$AJ,25,FALSE) -> #N/A | E10: =VLOOKUP($A10,'2026-2027 projections'!$B:$AJ,26,FALSE) -> #N/A | F10: =VLOOKUP($A10,'2026-2027 projections'!$B:$AJ,27,FALSE) -> #N/A | G10: =VLOOKUP($A10,'2026-2027 projections'!$B:$AJ,28,FALSE) -> #N/A | H10: =VLOOKUP($A10,'2026-2027 projections'!$B:$AJ,29,FALSE) -> #N/A | I10: =VLOOKUP($A10,'2026-2027 projections'!$B:$AJ,30,FALSE) -> #N/A | J10: =VLOOKUP($A10,'2026-2027 projections'!$B:$AJ,31,FALSE) -> #N/A | M10: =VLOOKUP(L10,#REF!,2,FALSE) -> #REF! | N10: =VLOOKUP(L10,#REF!,3,FALSE) -> #REF! | O10: =VLOOKUP($L10,'2026-2027 projections'!$B:$AJ,23,FALSE) -> #N/A | P10: =VLOOKUP($L10,'2026-2027 projections'!$B:$AJ,24,FALSE) -> #N/A | Q10: =VLOOKUP($L10,'2026-2027 projections'!$B:$AJ,25,FALSE) -> #N/A | R10: =VLOOKUP($L10,'2026-2027 projections'!$B:$AJ,26,FALSE) -> #N/A | S10: =VLOOKUP($L10,'2026-2027 projections'!$B:$AJ,27,FALSE) -> #N/A | T10: =VLOOKUP($L10,'2026-2027 projections'!$B:$AJ,28,FALSE) -> #N/A | U10: =VLOOKUP($L10,'2026-2027 projections'!$B:$AJ,29,FALSE) -> #N/A | V10: =VLOOKUP($L10,'2026-2027 projections'!$B:$AJ,30,FALSE) -> #N/A | W10: =VLOOKUP($L10,'2026-2027 projections'!$B:$AJ,31,FALSE) -> #N/A
B11: =VLOOKUP($A11,'2026-2027 projections'!$B:$AJ,23,FALSE) -> #N/A | C11: =VLOOKUP($A11,'2026-2027 projections'!$B:$AJ,24,FALSE) -> #N/A | D11: =VLOOKUP($A11,'2026-2027 projections'!$B:$AJ,25,FALSE) -> #N/A | E11: =VLOOKUP($A11,'2026-2027 projections'!$B:$AJ,26,FALSE) -> #N/A | F11: =VLOOKUP($A11,'2026-2027 projections'!$B:$AJ,27,FALSE) -> #N/A | G11: =VLOOKUP($A11,'2026-2027 projections'!$B:$AJ,28,FALSE) -> #N/A | H11: =VLOOKUP($A11,'2026-2027 projections'!$B:$AJ,29,FALSE) -> #N/A | I11: =VLOOKUP($A11,'2026-2027 projections'!$B:$AJ,30,FALSE) -> #N/A | J11: =VLOOKUP($A11,'2026-2027 projections'!$B:$AJ,31,FALSE) -> #N/A | AA11: =IFERROR(VLOOKUP($A11,'2026-2027 projections'!$B:$AF,20,FALSE),"") | AC11: FG% | AD11: FT% | AE11: 3PM | AF11: PTS | AG11: TREB | AH11: AST | AI11: STL | AJ11: BLK | AK11: TO
B12: =VLOOKUP($A12,'2026-2027 projections'!$B:$AJ,23,FALSE) -> #N/A | C12: =VLOOKUP($A12,'2026-2027 projections'!$B:$AJ,24,FALSE) -> #N/A | D12: =VLOOKUP($A12,'2026-2027 projections'!$B:$AJ,25,FALSE) -> #N/A | E12: =VLOOKUP($A12,'2026-2027 projections'!$B:$AJ,26,FALSE) -> #N/A | F12: =VLOOKUP($A12,'2026-2027 projections'!$B:$AJ,27,FALSE) -> #N/A | G12: =VLOOKUP($A12,'2026-2027 projections'!$B:$AJ,28,FALSE) -> #N/A | H12: =VLOOKUP($A12,'2026-2027 projections'!$B:$AJ,29,FALSE) -> #N/A | I12: =VLOOKUP($A12,'2026-2027 projections'!$B:$AJ,30,FALSE) -> #N/A | J12: =VLOOKUP($A12,'2026-2027 projections'!$B:$AJ,31,FALSE) -> #N/A | Z12: New Players | AB12: Before | AC12: =AVERAGEIF(#REF!, "<>#N/A") -> #REF! | AD12: =AVERAGEIF(#REF!, "<>#N/A") -> #REF! | AE12: =AVERAGEIF(#REF!, "<>#N/A") -> #REF! | AF12: =AVERAGEIF(#REF!, "<>#N/A") -> #REF! | AG12: =AVERAGEIF(#REF!, "<>#N/A") -> #REF! | AH12: =AVERAGEIF(#REF!, "<>#N/A") -> #REF! | AI12: =AVERAGEIF(#REF!, "<>#N/A") -> #REF! | AJ12: =AVERAGEIF(#REF!, "<>#N/A") -> #REF! | AK12: =AVERAGEIF(#REF!, "<>#N/A") -> #REF!
B13: =VLOOKUP($A13,'2026-2027 projections'!$B:$AJ,23,FALSE) -> #N/A | C13: =VLOOKUP($A13,'2026-2027 projections'!$B:$AJ,24,FALSE) -> #N/A | D13: =VLOOKUP($A13,'2026-2027 projections'!$B:$AJ,25,FALSE) -> #N/A | E13: =VLOOKUP($A13,'2026-2027 projections'!$B:$AJ,26,FALSE) -> #N/A | F13: =VLOOKUP($A13,'2026-2027 projections'!$B:$AJ,27,FALSE) -> #N/A | G13: =VLOOKUP($A13,'2026-2027 projections'!$B:$AJ,28,FALSE) -> #N/A | H13: =VLOOKUP($A13,'2026-2027 projections'!$B:$AJ,29,FALSE) -> #N/A | I13: =VLOOKUP($A13,'2026-2027 projections'!$B:$AJ,30,FALSE) -> #N/A | J13: =VLOOKUP($A13,'2026-2027 projections'!$B:$AJ,31,FALSE) -> #N/A | L13: Rd3-4 | M13: Fair Value | N13: LY Rank | O13: FG% | P13: FT% | Q13: 3PM | R13: PTS | S13: TREB | T13: AST | U13: STL | V13: BLK | W13: TO | Z13: James Harden | AB13: After | AC13: =SUM(#REF!,#REF!)/SUM(#REF!,#REF!) -> #REF! | AD13: =SUM(#REF!,AA11)/SUM(#REF!,#REF!) -> #REF! | AE13: =AVERAGE(#REF!,AE11) -> #REF! | AF13: =AVERAGE(#REF!,AF11) -> #REF! | AG13: =AVERAGE(#REF!,AG11) -> #REF! | AH13: =AVERAGE(#REF!,AH11) -> #REF! | AI13: =AVERAGE(#REF!,AI11) -> #REF! | AJ13: =AVERAGE(#REF!,AJ11) -> #REF! | AK13: =AVERAGE(#REF!,AK11) -> #REF!
B14: =VLOOKUP($A14,'2026-2027 projections'!$B:$AJ,23,FALSE) -> #N/A | C14: =VLOOKUP($A14,'2026-2027 projections'!$B:$AJ,24,FALSE) -> #N/A | D14: =VLOOKUP($A14,'2026-2027 projections'!$B:$AJ,25,FALSE) -> #N/A | E14: =VLOOKUP($A14,'2026-2027 projections'!$B:$AJ,26,FALSE) -> #N/A | F14: =VLOOKUP($A14,'2026-2027 projections'!$B:$AJ,27,FALSE) -> #N/A | G14: =VLOOKUP($A14,'2026-2027 projections'!$B:$AJ,28,FALSE) -> #N/A | H14: =VLOOKUP($A14,'2026-2027 projections'!$B:$AJ,29,FALSE) -> #N/A | I14: =VLOOKUP($A14,'2026-2027 projections'!$B:$AJ,30,FALSE) -> #N/A | J14: =VLOOKUP($A14,'2026-2027 projections'!$B:$AJ,31,FALSE) -> #N/A | L14: Scottie Barnes | M14: =VLOOKUP(L14,'2026-2027 projections'!B:C,2,FALSE) -> 20 | N14: =VLOOKUP(L14,'2026-2027 projections'!B:D,3,FALSE) -> 16 | O14: =VLOOKUP($L14,'2026-2027 projections'!$B:$AJ,23,FALSE) -> -0.1435274 | P14: =VLOOKUP($L14,'2026-2027 projections'!$B:$AJ,24,FALSE) -> -0.063018339 | Q14: =VLOOKUP($L14,'2026-2027 projections'!$B:$AJ,25,FALSE) -> -0.70196065 | R14: =VLOOKUP($L14,'2026-2027 projections'!$B:$AJ,26,FALSE) -> 0.66308044 | S14: =VLOOKUP($L14,'2026-2027 projections'!$B:$AJ,27,FALSE) -> 0.92127976 | T14: =VLOOKUP($L14,'2026-2027 projections'!$B:$AJ,28,FALSE) -> 1.2653723 | U14: =VLOOKUP($L14,'2026-2027 projections'!$B:$AJ,29,FALSE) -> 1.419362 | V14: =VLOOKUP($L14,'2026-2027 projections'!$B:$AJ,30,FALSE) -> 1.2616238 | W14: =VLOOKUP($L14,'2026-2027 projections'!$B:$AJ,31,FALSE) -> -1.3021698 | AB14: Delta | AC14: =AC13-AC12 -> #REF! | AD14: =AD13-AD12 -> #REF! | AE14: =AE13-AE12 -> #REF! | AF14: =AF13-AF12 -> #REF! | AG14: =AG13-AG12 -> #REF! | AH14: =AH13-AH12 -> #REF! | AI14: =AI13-AI12 -> #REF! | AJ14: =AJ13-AJ12 -> #REF! | AK14: =AK13-AK12 -> #REF!
B15: =VLOOKUP($A15,'2026-2027 projections'!$B:$AJ,23,FALSE) -> #N/A | C15: =VLOOKUP($A15,'2026-2027 projections'!$B:$AJ,24,FALSE) -> #N/A | D15: =VLOOKUP($A15,'2026-2027 projections'!$B:$AJ,25,FALSE) -> #N/A | E15: =VLOOKUP($A15,'2026-2027 projections'!$B:$AJ,26,FALSE) -> #N/A | F15: =VLOOKUP($A15,'2026-2027 projections'!$B:$AJ,27,FALSE) -> #N/A | G15: =VLOOKUP($A15,'2026-2027 projections'!$B:$AJ,28,FALSE) -> #N/A | H15: =VLOOKUP($A15,'2026-2027 projections'!$B:$AJ,29,FALSE) -> #N/A | I15: =VLOOKUP($A15,'2026-2027 projections'!$B:$AJ,30,FALSE) -> #N/A | J15: =VLOOKUP($A15,'2026-2027 projections'!$B:$AJ,31,FALSE) -> #N/A | M15: =VLOOKUP(L15,'2026-2027 projections'!B:C,2,FALSE) -> #N/A | N15: =VLOOKUP(L15,'2026-2027 projections'!B:D,3,FALSE) -> #N/A | O15: =VLOOKUP($L15,'2026-2027 projections'!$B:$AJ,23,FALSE) -> #N/A | P15: =VLOOKUP($L15,'2026-2027 projections'!$B:$AJ,24,FALSE) -> #N/A | Q15: =VLOOKUP($L15,'2026-2027 projections'!$B:$AJ,25,FALSE) -> #N/A | R15: =VLOOKUP($L15,'2026-2027 projections'!$B:$AJ,26,FALSE) -> #N/A | S15: =VLOOKUP($L15,'2026-2027 projections'!$B:$AJ,27,FALSE) -> #N/A | T15: =VLOOKUP($L15,'2026-2027 projections'!$B:$AJ,28,FALSE) -> #N/A | U15: =VLOOKUP($L15,'2026-2027 projections'!$B:$AJ,29,FALSE) -> #N/A | V15: =VLOOKUP($L15,'2026-2027 projections'!$B:$AJ,30,FALSE) -> #N/A | W15: =VLOOKUP($L15,'2026-2027 projections'!$B:$AJ,31,FALSE) -> #N/A | AC15: FG% | AD15: FT% | AE15: 3PM | AF15: PTS | AG15: Reb | AH15: AST | AI15: STL | AJ15: BLK | AK15: TO
B16: =VLOOKUP($A16,'2026-2027 projections'!$B:$AJ,23,FALSE) -> #N/A | C16: =VLOOKUP($A16,'2026-2027 projections'!$B:$AJ,24,FALSE) -> #N/A | D16: =VLOOKUP($A16,'2026-2027 projections'!$B:$AJ,25,FALSE) -> #N/A | E16: =VLOOKUP($A16,'2026-2027 projections'!$B:$AJ,26,FALSE) -> #N/A | F16: =VLOOKUP($A16,'2026-2027 projections'!$B:$AJ,27,FALSE) -> #N/A | G16: =VLOOKUP($A16,'2026-2027 projections'!$B:$AJ,28,FALSE) -> #N/A | H16: =VLOOKUP($A16,'2026-2027 projections'!$B:$AJ,29,FALSE) -> #N/A | I16: =VLOOKUP($A16,'2026-2027 projections'!$B:$AJ,30,FALSE) -> #N/A | J16: =VLOOKUP($A16,'2026-2027 projections'!$B:$AJ,31,FALSE) -> #N/A | L16: Damian Lillard | M16: =VLOOKUP(L16,'2026-2027 projections'!B:C,2,FALSE) -> 75 | N16: =VLOOKUP(L16,'2026-2027 projections'!B:D,3,FALSE) -> #N/A | O16: =VLOOKUP($L16,'2026-2027 projections'!$B:$AJ,23,FALSE) -> -1.0517581 | P16: =VLOOKUP($L16,'2026-2027 projections'!$B:$AJ,24,FALSE) -> 1.4790144 | Q16: =VLOOKUP($L16,'2026-2027 projections'!$B:$AJ,25,FALSE) -> 1.5075665 | R16: =VLOOKUP($L16,'2026-2027 projections'!$B:$AJ,26,FALSE) -> 0.60629341 | S16: =VLOOKUP($L16,'2026-2027 projections'!$B:$AJ,27,FALSE) -> -0.90968613 | T16: =VLOOKUP($L16,'2026-2027 projections'!$B:$AJ,28,FALSE) -> 0.69741898 | U16: =VLOOKUP($L16,'2026-2027 projections'!$B:$AJ,29,FALSE) -> -0.34169827 | V16: =VLOOKUP($L16,'2026-2027 projections'!$B:$AJ,30,FALSE) -> -1.1747546 | W16: =VLOOKUP($L16,'2026-2027 projections'!$B:$AJ,31,FALSE) -> -0.34692845 | AB16: Before | AC16: =AC6 -> #REF! | AD16: =AD6 -> n/a | AE16: =AE6 -> #REF! | AF16: =AF6 -> #REF! | AG16: =AG6 -> #REF! | AH16: =AH6 -> #REF! | AI16: =AI6 -> #REF! | AJ16: =AJ6 -> #REF! | AK16: =AK6 -> #REF!
B17: =VLOOKUP($A17,'2026-2027 projections'!$B:$AJ,23,FALSE) -> #N/A | C17: =VLOOKUP($A17,'2026-2027 projections'!$B:$AJ,24,FALSE) -> #N/A | D17: =VLOOKUP($A17,'2026-2027 projections'!$B:$AJ,25,FALSE) -> #N/A | E17: =VLOOKUP($A17,'2026-2027 projections'!$B:$AJ,26,FALSE) -> #N/A | F17: =VLOOKUP($A17,'2026-2027 projections'!$B:$AJ,27,FALSE) -> #N/A | G17: =VLOOKUP($A17,'2026-2027 projections'!$B:$AJ,28,FALSE) -> #N/A | H17: =VLOOKUP($A17,'2026-2027 projections'!$B:$AJ,29,FALSE) -> #N/A | I17: =VLOOKUP($A17,'2026-2027 projections'!$B:$AJ,30,FALSE) -> #N/A | J17: =VLOOKUP($A17,'2026-2027 projections'!$B:$AJ,31,FALSE) -> #N/A | L17: De'Aaron Fox | M17: =VLOOKUP(L17,'2026-2027 projections'!B:C,2,FALSE) -> 87 | N17: =VLOOKUP(L17,'2026-2027 projections'!B:D,3,FALSE) -> 71 | O17: =VLOOKUP($L17,'2026-2027 projections'!$B:$AJ,23,FALSE) -> 0.0022977864 | P17: =VLOOKUP($L17,'2026-2027 projections'!$B:$AJ,24,FALSE) -> -0.00056220741 | Q17: =VLOOKUP($L17,'2026-2027 projections'!$B:$AJ,25,FALSE) -> 0.034548399 | R17: =VLOOKUP($L17,'2026-2027 projections'!$B:$AJ,26,FALSE) -> 0.56843539 | S17: =VLOOKUP($L17,'2026-2027 projections'!$B:$AJ,27,FALSE) -> -0.74323469 | T17: =VLOOKUP($L17,'2026-2027 projections'!$B:$AJ,28,FALSE) -> 1.110476 | U17: =VLOOKUP($L17,'2026-2027 projections'!$B:$AJ,29,FALSE) -> 0.53883188 | V17: =VLOOKUP($L17,'2026-2027 projections'!$B:$AJ,30,FALSE) -> -0.76869155 | W17: =VLOOKUP($L17,'2026-2027 projections'!$B:$AJ,31,FALSE) -> -0.61985455 | AB17: Delta | AC17: =AC18-AC16 -> #REF! | AD17: =AD18-AD16 -> #REF! | AE17: =AE18-AE16 -> #REF! | AF17: =AF18-AF16 -> #REF! | AG17: =AG18-AG16 -> #REF! | AH17: =AH18-AH16 -> #REF! | AI17: =AI18-AI16 -> #REF! | AJ17: =AJ18-AJ16 -> #REF! | AK17: =AK18-AK16 -> #REF!
B18: =VLOOKUP($A18,'2026-2027 projections'!$B:$AJ,23,FALSE) -> #N/A | C18: =VLOOKUP($A18,'2026-2027 projections'!$B:$AJ,24,FALSE) -> #N/A | D18: =VLOOKUP($A18,'2026-2027 projections'!$B:$AJ,25,FALSE) -> #N/A | E18: =VLOOKUP($A18,'2026-2027 projections'!$B:$AJ,26,FALSE) -> #N/A | F18: =VLOOKUP($A18,'2026-2027 projections'!$B:$AJ,27,FALSE) -> #N/A | G18: =VLOOKUP($A18,'2026-2027 projections'!$B:$AJ,28,FALSE) -> #N/A | H18: =VLOOKUP($A18,'2026-2027 projections'!$B:$AJ,29,FALSE) -> #N/A | I18: =VLOOKUP($A18,'2026-2027 projections'!$B:$AJ,30,FALSE) -> #N/A | J18: =VLOOKUP($A18,'2026-2027 projections'!$B:$AJ,31,FALSE) -> #N/A | L18: Tyrese Maxey | M18: =VLOOKUP(L18,'2026-2027 projections'!B:C,2,FALSE) -> 6 | N18: =VLOOKUP(L18,'2026-2027 projections'!B:D,3,FALSE) -> 4 | O18: =VLOOKUP($L18,'2026-2027 projections'!$B:$AJ,23,FALSE) -> -0.70814713 | P18: =VLOOKUP($L18,'2026-2027 projections'!$B:$AJ,24,FALSE) -> 1.6216106 | Q18: =VLOOKUP($L18,'2026-2027 projections'!$B:$AJ,25,FALSE) -> 1.1919198 | R18: =VLOOKUP($L18,'2026-2027 projections'!$B:$AJ,26,FALSE) -> 1.571673 | S18: =VLOOKUP($L18,'2026-2027 projections'!$B:$AJ,27,FALSE) -> -0.95129899 | T18: =VLOOKUP($L18,'2026-2027 projections'!$B:$AJ,28,FALSE) -> 1.110476 | U18: =VLOOKUP($L18,'2026-2027 projections'!$B:$AJ,29,FALSE) -> 2.2998922 | V18: =VLOOKUP($L18,'2026-2027 projections'!$B:$AJ,30,FALSE) -> -0.36262847 | W18: =VLOOKUP($L18,'2026-2027 projections'!$B:$AJ,31,FALSE) -> -0.4833915 | AB18: After | AC18: =((SUM(#REF!,#REF!)/SUM(#REF!,#REF!))-#REF!)/#REF!*SQRT(SUM(#REF!,#REF!)/(COUNT(#REF!,#REF!)*#REF!)) -> #REF! | AD18: =((SUM(#REF!,AA11)/SUM(#REF!,#REF!)-#REF!)/#REF!)*SQRT(SUM(#REF!,#REF!)/(COUNT(#REF!,#REF!)*#REF!)) -> #REF! | AE18: =(AVERAGE(#REF!,AE11)-#REF!)/#REF! -> #REF! | AF18: =(AVERAGE(#REF!,AF11)-#REF!)/#REF! -> #REF! | AG18: =(AVERAGE(#REF!,AG11)-#REF!)/#REF! -> #REF! | AH18: =(AVERAGE(#REF!,AH11)-#REF!)/#REF! -> #REF! | AI18: =(AVERAGE(#REF!,AI11)-#REF!)/#REF! -> #REF! | AJ18: =(AVERAGE(#REF!,AJ11)-#REF!)/#REF! -> #REF! | AK18: =(AVERAGE(#REF!,AK11)-#REF!)/#REF!*-1 -> #REF!
B19: =VLOOKUP($A19,'2026-2027 projections'!$B:$AJ,23,FALSE) -> #N/A | C19: =VLOOKUP($A19,'2026-2027 projections'!$B:$AJ,24,FALSE) -> #N/A | D19: =VLOOKUP($A19,'2026-2027 projections'!$B:$AJ,25,FALSE) -> #N/A | E19: =VLOOKUP($A19,'2026-2027 projections'!$B:$AJ,26,FALSE) -> #N/A | F19: =VLOOKUP($A19,'2026-2027 projections'!$B:$AJ,27,FALSE) -> #N/A | G19: =VLOOKUP($A19,'2026-2027 projections'!$B:$AJ,28,FALSE) -> #N/A | H19: =VLOOKUP($A19,'2026-2027 projections'!$B:$AJ,29,FALSE) -> #N/A | I19: =VLOOKUP($A19,'2026-2027 projections'!$B:$AJ,30,FALSE) -> #N/A | J19: =VLOOKUP($A19,'2026-2027 projections'!$B:$AJ,31,FALSE) -> #N/A | L19: Jalen Williams | M19: =VLOOKUP(L19,'2026-2027 projections'!B:C,2,FALSE) -> 32 | N19: =VLOOKUP(L19,'2026-2027 projections'!B:D,3,FALSE) -> 78 | O19: =VLOOKUP($L19,'2026-2027 projections'!$B:$AJ,23,FALSE) -> 0.14220234 | P19: =VLOOKUP($L19,'2026-2027 projections'!$B:$AJ,24,FALSE) -> -0.063018339 | Q19: =VLOOKUP($L19,'2026-2027 projections'!$B:$AJ,25,FALSE) -> -0.17588276 | R19: =VLOOKUP($L19,'2026-2027 projections'!$B:$AJ,26,FALSE) -> 0.85237056 | S19: =VLOOKUP($L19,'2026-2027 projections'!$B:$AJ,27,FALSE) -> -0.20226749 | T19: =VLOOKUP($L19,'2026-2027 projections'!$B:$AJ,28,FALSE) -> 0.85231535 | U19: =VLOOKUP($L19,'2026-2027 projections'!$B:$AJ,29,FALSE) -> 1.419362 | V19: =VLOOKUP($L19,'2026-2027 projections'!$B:$AJ,30,FALSE) -> -0.15959693 | W19: =VLOOKUP($L19,'2026-2027 projections'!$B:$AJ,31,FALSE) -> -0.34692845
B20: =VLOOKUP($A20,'2026-2027 projections'!$B:$AJ,23,FALSE) -> #N/A | C20: =VLOOKUP($A20,'2026-2027 projections'!$B:$AJ,24,FALSE) -> #N/A | D20: =VLOOKUP($A20,'2026-2027 projections'!$B:$AJ,25,FALSE) -> #N/A | E20: =VLOOKUP($A20,'2026-2027 projections'!$B:$AJ,26,FALSE) -> #N/A | F20: =VLOOKUP($A20,'2026-2027 projections'!$B:$AJ,27,FALSE) -> #N/A | G20: =VLOOKUP($A20,'2026-2027 projections'!$B:$AJ,28,FALSE) -> #N/A | H20: =VLOOKUP($A20,'2026-2027 projections'!$B:$AJ,29,FALSE) -> #N/A | I20: =VLOOKUP($A20,'2026-2027 projections'!$B:$AJ,30,FALSE) -> #N/A | J20: =VLOOKUP($A20,'2026-2027 projections'!$B:$AJ,31,FALSE) -> #N/A | L20: Alperen Sengun | M20: =VLOOKUP(L20,'2026-2027 projections'!B:C,2,FALSE) -> #N/A | N20: =VLOOKUP(L20,'2026-2027 projections'!B:D,3,FALSE) -> #N/A | O20: =VLOOKUP($L20,'2026-2027 projections'!$B:$AJ,23,FALSE) -> #N/A | P20: =VLOOKUP($L20,'2026-2027 projections'!$B:$AJ,24,FALSE) -> #N/A | Q20: =VLOOKUP($L20,'2026-2027 projections'!$B:$AJ,25,FALSE) -> #N/A | R20: =VLOOKUP($L20,'2026-2027 projections'!$B:$AJ,26,FALSE) -> #N/A | S20: =VLOOKUP($L20,'2026-2027 projections'!$B:$AJ,27,FALSE) -> #N/A | T20: =VLOOKUP($L20,'2026-2027 projections'!$B:$AJ,28,FALSE) -> #N/A | U20: =VLOOKUP($L20,'2026-2027 projections'!$B:$AJ,29,FALSE) -> #N/A | V20: =VLOOKUP($L20,'2026-2027 projections'!$B:$AJ,30,FALSE) -> #N/A | W20: =VLOOKUP($L20,'2026-2027 projections'!$B:$AJ,31,FALSE) -> #N/A
L21: Lauri Markkanen | M21: =VLOOKUP(L21,'2026-2027 projections'!B:C,2,FALSE) -> 27 | N21: =VLOOKUP(L21,'2026-2027 projections'!B:D,3,FALSE) -> 17 | O21: =VLOOKUP($L21,'2026-2027 projections'!$B:$AJ,23,FALSE) -> -1.0891201 | P21: =VLOOKUP($L21,'2026-2027 projections'!$B:$AJ,24,FALSE) -> 1.4165582 | Q21: =VLOOKUP($L21,'2026-2027 projections'!$B:$AJ,25,FALSE) -> 1.4023509 | R21: =VLOOKUP($L21,'2026-2027 projections'!$B:$AJ,26,FALSE) -> 1.4959569 | S21: =VLOOKUP($L21,'2026-2027 projections'!$B:$AJ,27,FALSE) -> 0.42192543 | T21: =VLOOKUP($L21,'2026-2027 projections'!$B:$AJ,28,FALSE) -> -0.90317685 | U21: =VLOOKUP($L21,'2026-2027 projections'!$B:$AJ,29,FALSE) -> -0.34169827 | V21: =VLOOKUP($L21,'2026-2027 projections'!$B:$AJ,30,FALSE) -> -0.36262847 | W21: =VLOOKUP($L21,'2026-2027 projections'!$B:$AJ,31,FALSE) -> 0.47184985
L22: Fred Vanvleet | M22: =VLOOKUP(L22,'2026-2027 projections'!B:C,2,FALSE) -> 102 | N22: =VLOOKUP(L22,'2026-2027 projections'!B:D,3,FALSE) -> #N/A | O22: =VLOOKUP($L22,'2026-2027 projections'!$B:$AJ,23,FALSE) -> -2 | P22: =VLOOKUP($L22,'2026-2027 projections'!$B:$AJ,24,FALSE) -> 0.38301657 | Q22: =VLOOKUP($L22,'2026-2027 projections'!$B:$AJ,25,FALSE) -> 0.77105745 | R22: =VLOOKUP($L22,'2026-2027 projections'!$B:$AJ,26,FALSE) -> -0.62409233 | S22: =VLOOKUP($L22,'2026-2027 projections'!$B:$AJ,27,FALSE) -> -0.99291185 | T22: =VLOOKUP($L22,'2026-2027 projections'!$B:$AJ,28,FALSE) -> 0.69741898 | U22: =VLOOKUP($L22,'2026-2027 projections'!$B:$AJ,29,FALSE) -> 1.125852 | V22: =VLOOKUP($L22,'2026-2027 projections'!$B:$AJ,30,FALSE) -> -0.56566001 | W22: =VLOOKUP($L22,'2026-2027 projections'!$B:$AJ,31,FALSE) -> 0.74477594
B23: FG% | C23: FT% | D23: 3PM | E23: PTS | F23: TREB | G23: AST | H23: STL | I23: BLK | J23: TO | L23: Ja Morant | M23: =VLOOKUP(L23,'2026-2027 projections'!B:C,2,FALSE) -> 139 | N23: =VLOOKUP(L23,'2026-2027 projections'!B:D,3,FALSE) -> 69 | O23: =VLOOKUP($L23,'2026-2027 projections'!$B:$AJ,23,FALSE) -> -0.55002113 | P23: =VLOOKUP($L23,'2026-2027 projections'!$B:$AJ,24,FALSE) -> 0.79255911 | Q23: =VLOOKUP($L23,'2026-2027 projections'!$B:$AJ,25,FALSE) -> -0.28109834 | R23: =VLOOKUP($L23,'2026-2027 projections'!$B:$AJ,26,FALSE) -> 0.68200945 | S23: =VLOOKUP($L23,'2026-2027 projections'!$B:$AJ,27,FALSE) -> -0.95129899 | T23: =VLOOKUP($L23,'2026-2027 projections'!$B:$AJ,28,FALSE) -> 1.523533 | U23: =VLOOKUP($L23,'2026-2027 projections'!$B:$AJ,29,FALSE) -> -0.048188217 | V23: =VLOOKUP($L23,'2026-2027 projections'!$B:$AJ,30,FALSE) -> -0.97172309 | W23: =VLOOKUP($L23,'2026-2027 projections'!$B:$AJ,31,FALSE) -> -1.848022
B24: =AVERAGEIF(B1:B15, "<>#N/A") -> 1.3737546 | C24: =AVERAGEIF(C1:C15, "<>#N/A") -> 0.64112088 | D24: =AVERAGEIF(D1:D15, "<>#N/A") -> 0.66584187 | E24: =AVERAGEIF(E1:E15, "<>#N/A") -> 1.3161313 | F24: =AVERAGEIF(F1:F15, "<>#N/A") -> 0.96289263 | G24: =AVERAGEIF(G1:G15, "<>#N/A") -> 3.2790252 | H24: =AVERAGEIF(H1:H15, "<>#N/A") -> 1.272607 | I24: =AVERAGEIF(I1:I15, "<>#N/A") -> -0.058081162 | J24: =AVERAGEIF(J1:J15, "<>#N/A") -> -0.90053813 | L24: Cade Cunningham | M24: =VLOOKUP(L24,'2026-2027 projections'!B:C,2,FALSE) -> 10 | N24: =VLOOKUP(L24,'2026-2027 projections'!B:D,3,FALSE) -> 13 | O24: =VLOOKUP($L24,'2026-2027 projections'!$B:$AJ,23,FALSE) -> -0.56824258 | P24: =VLOOKUP($L24,'2026-2027 projections'!$B:$AJ,24,FALSE) -> 0.51620862 | Q24: =VLOOKUP($L24,'2026-2027 projections'!$B:$AJ,25,FALSE) -> 0.35019514 | R24: =VLOOKUP($L24,'2026-2027 projections'!$B:$AJ,26,FALSE) -> 1.7231051 | S24: =VLOOKUP($L24,'2026-2027 projections'!$B:$AJ,27,FALSE) -> 0.047409678 | T24: =VLOOKUP($L24,'2026-2027 projections'!$B:$AJ,28,FALSE) -> 3.1757609 | U24: =VLOOKUP($L24,'2026-2027 projections'!$B:$AJ,29,FALSE) -> 0.83234193 | V24: =VLOOKUP($L24,'2026-2027 projections'!$B:$AJ,30,FALSE) -> 0.24646615 | W24: =VLOOKUP($L24,'2026-2027 projections'!$B:$AJ,31,FALSE) -> -2
J25: =AVERAGE(B24:J24) -> 0.95030602 | M25: =VLOOKUP(L25,'2026-2027 projections'!B:C,2,FALSE) -> #N/A | N25: =VLOOKUP(L25,'2026-2027 projections'!B:D,3,FALSE) -> #N/A | O25: =VLOOKUP($L25,'2026-2027 projections'!$B:$AJ,23,FALSE) -> #N/A | P25: =VLOOKUP($L25,'2026-2027 projections'!$B:$AJ,24,FALSE) -> #N/A | Q25: =VLOOKUP($L25,'2026-2027 projections'!$B:$AJ,25,FALSE) -> #N/A | R25: =VLOOKUP($L25,'2026-2027 projections'!$B:$AJ,26,FALSE) -> #N/A | S25: =VLOOKUP($L25,'2026-2027 projections'!$B:$AJ,27,FALSE) -> #N/A | T25: =VLOOKUP($L25,'2026-2027 projections'!$B:$AJ,28,FALSE) -> #N/A | U25: =VLOOKUP($L25,'2026-2027 projections'!$B:$AJ,29,FALSE) -> #N/A | V25: =VLOOKUP($L25,'2026-2027 projections'!$B:$AJ,30,FALSE) -> #N/A | W25: =VLOOKUP($L25,'2026-2027 projections'!$B:$AJ,31,FALSE) -> #N/A
M26: =VLOOKUP(L26,'2026-2027 projections'!B:C,2,FALSE) -> #N/A | N26: =VLOOKUP(L26,'2026-2027 projections'!B:D,3,FALSE) -> #N/A | O26: =VLOOKUP($L26,'2026-2027 projections'!$B:$AJ,23,FALSE) -> #N/A | P26: =VLOOKUP($L26,'2026-2027 projections'!$B:$AJ,24,FALSE) -> #N/A | Q26: =VLOOKUP($L26,'2026-2027 projections'!$B:$AJ,25,FALSE) -> #N/A | R26: =VLOOKUP($L26,'2026-2027 projections'!$B:$AJ,26,FALSE) -> #N/A | S26: =VLOOKUP($L26,'2026-2027 projections'!$B:$AJ,27,FALSE) -> #N/A | T26: =VLOOKUP($L26,'2026-2027 projections'!$B:$AJ,28,FALSE) -> #N/A | U26: =VLOOKUP($L26,'2026-2027 projections'!$B:$AJ,29,FALSE) -> #N/A | V26: =VLOOKUP($L26,'2026-2027 projections'!$B:$AJ,30,FALSE) -> #N/A | W26: =VLOOKUP($L26,'2026-2027 projections'!$B:$AJ,31,FALSE) -> #N/A
M27: =VLOOKUP(L27,'2026-2027 projections'!B:C,2,FALSE) -> #N/A | N27: =VLOOKUP(L27,'2026-2027 projections'!B:D,3,FALSE) -> #N/A | O27: =VLOOKUP($L27,'2026-2027 projections'!$B:$AJ,23,FALSE) -> #N/A | P27: =VLOOKUP($L27,'2026-2027 projections'!$B:$AJ,24,FALSE) -> #N/A | Q27: =VLOOKUP($L27,'2026-2027 projections'!$B:$AJ,25,FALSE) -> #N/A | R27: =VLOOKUP($L27,'2026-2027 projections'!$B:$AJ,26,FALSE) -> #N/A | S27: =VLOOKUP($L27,'2026-2027 projections'!$B:$AJ,27,FALSE) -> #N/A | T27: =VLOOKUP($L27,'2026-2027 projections'!$B:$AJ,28,FALSE) -> #N/A | U27: =VLOOKUP($L27,'2026-2027 projections'!$B:$AJ,29,FALSE) -> #N/A | V27: =VLOOKUP($L27,'2026-2027 projections'!$B:$AJ,30,FALSE) -> #N/A | W27: =VLOOKUP($L27,'2026-2027 projections'!$B:$AJ,31,FALSE) -> #N/A
M28: =VLOOKUP(L28,'2026-2027 projections'!B:C,2,FALSE) -> #N/A | N28: =VLOOKUP(L28,'2026-2027 projections'!B:D,3,FALSE) -> #N/A | O28: =VLOOKUP($L28,'2026-2027 projections'!$B:$AJ,23,FALSE) -> #N/A | P28: =VLOOKUP($L28,'2026-2027 projections'!$B:$AJ,24,FALSE) -> #N/A | Q28: =VLOOKUP($L28,'2026-2027 projections'!$B:$AJ,25,FALSE) -> #N/A | R28: =VLOOKUP($L28,'2026-2027 projections'!$B:$AJ,26,FALSE) -> #N/A | S28: =VLOOKUP($L28,'2026-2027 projections'!$B:$AJ,27,FALSE) -> #N/A | T28: =VLOOKUP($L28,'2026-2027 projections'!$B:$AJ,28,FALSE) -> #N/A | U28: =VLOOKUP($L28,'2026-2027 projections'!$B:$AJ,29,FALSE) -> #N/A | V28: =VLOOKUP($L28,'2026-2027 projections'!$B:$AJ,30,FALSE) -> #N/A | W28: =VLOOKUP($L28,'2026-2027 projections'!$B:$AJ,31,FALSE) -> #N/A
A30: Player | B30: FG% | C30: FT% | D30: 3PM | E30: PTS | F30: TREB | G30: AST | H30: STL | I30: BLK | J30: TO
A31: =A$2 -> Nikola Jokic | B31: =VLOOKUP($A31,'2026-2027 projections'!$B:$AJ,23,FALSE) -> 3.0692222 | C31: =VLOOKUP($A31,'2026-2027 projections'!$B:$AJ,24,FALSE) -> 0.67648884 | D31: =VLOOKUP($A31,'2026-2027 projections'!$B:$AJ,25,FALSE) -> 0.13976398 | E31: =VLOOKUP($A31,'2026-2027 projections'!$B:$AJ,26,FALSE) -> 2.3666915 | F31: =VLOOKUP($A31,'2026-2027 projections'!$B:$AJ,27,FALSE) -> 2.9186971 | G31: =VLOOKUP($A31,'2026-2027 projections'!$B:$AJ,28,FALSE) -> 3.4855537 | H31: =VLOOKUP($A31,'2026-2027 projections'!$B:$AJ,29,FALSE) -> 1.7128721 | I31: =VLOOKUP($A31,'2026-2027 projections'!$B:$AJ,30,FALSE) -> 0.043434608 | J31: =VLOOKUP($A31,'2026-2027 projections'!$B:$AJ,31,FALSE) -> -2 | L31: Rd 5-6 | M31: Fair Value | N31: LY Rank | O31: FG% | P31: FT% | Q31: 3PM | R31: PTS | S31: TREB | T31: AST | U31: STL | V31: BLK | W31: TO
A32: =A$3 -> Tyrese Haliburton | B32: =VLOOKUP($A32,'2026-2027 projections'!$B:$AJ,23,FALSE) -> -0.32171307 | C32: =VLOOKUP($A32,'2026-2027 projections'!$B:$AJ,24,FALSE) -> 0.60575292 | D32: =VLOOKUP($A32,'2026-2027 projections'!$B:$AJ,25,FALSE) -> 1.1919198 | E32: =VLOOKUP($A32,'2026-2027 projections'!$B:$AJ,26,FALSE) -> 0.2655712 | F32: =VLOOKUP($A32,'2026-2027 projections'!$B:$AJ,27,FALSE) -> -0.99291185 | G32: =VLOOKUP($A32,'2026-2027 projections'!$B:$AJ,28,FALSE) -> 3.0724967 | H32: =VLOOKUP($A32,'2026-2027 projections'!$B:$AJ,29,FALSE) -> 0.83234193 | I32: =VLOOKUP($A32,'2026-2027 projections'!$B:$AJ,30,FALSE) -> -0.15959693 | J32: =VLOOKUP($A32,'2026-2027 projections'!$B:$AJ,31,FALSE) -> 0.19892375 | L32: Desmond Bane | M32: =VLOOKUP(L32,'2026-2027 projections'!B:C,2,FALSE) -> 35 | N32: =VLOOKUP(L32,'2026-2027 projections'!B:D,3,FALSE) -> 37 | O32: =VLOOKUP($L32,'2026-2027 projections'!$B:$AJ,23,FALSE) -> 0.0022977864 | P32: =VLOOKUP($L32,'2026-2027 projections'!$B:$AJ,24,FALSE) -> 1.4524884 | Q32: =VLOOKUP($L32,'2026-2027 projections'!$B:$AJ,25,FALSE) -> 0.56062629 | R32: =VLOOKUP($L32,'2026-2027 projections'!$B:$AJ,26,FALSE) -> 0.66308044 | S32: =VLOOKUP($L32,'2026-2027 projections'!$B:$AJ,27,FALSE) -> -0.32710607 | T32: =VLOOKUP($L32,'2026-2027 projections'!$B:$AJ,28,FALSE) -> 0.49089049 | U32: =VLOOKUP($L32,'2026-2027 projections'!$B:$AJ,29,FALSE) -> 0.24532183 | V32: =VLOOKUP($L32,'2026-2027 projections'!$B:$AJ,30,FALSE) -> -0.56566001 | W32: =VLOOKUP($L32,'2026-2027 projections'!$B:$AJ,31,FALSE) -> -0.4833915
A33: =A4 -> 0 | B33: =VLOOKUP($A33,'2026-2027 projections'!$B:$AJ,23,FALSE) -> #N/A | C33: =VLOOKUP($A33,'2026-2027 projections'!$B:$AJ,24,FALSE) -> #N/A | D33: =VLOOKUP($A33,'2026-2027 projections'!$B:$AJ,25,FALSE) -> #N/A | E33: =VLOOKUP($A33,'2026-2027 projections'!$B:$AJ,26,FALSE) -> #N/A | F33: =VLOOKUP($A33,'2026-2027 projections'!$B:$AJ,27,FALSE) -> #N/A | G33: =VLOOKUP($A33,'2026-2027 projections'!$B:$AJ,28,FALSE) -> #N/A | H33: =VLOOKUP($A33,'2026-2027 projections'!$B:$AJ,29,FALSE) -> #N/A | I33: =VLOOKUP($A33,'2026-2027 projections'!$B:$AJ,30,FALSE) -> #N/A | J33: =VLOOKUP($A33,'2026-2027 projections'!$B:$AJ,31,FALSE) -> #N/A | L33: Jimmy Butler | M33: =VLOOKUP(L33,'2026-2027 projections'!B:C,2,FALSE) -> #N/A | N33: =VLOOKUP(L33,'2026-2027 projections'!B:D,3,FALSE) -> #N/A | O33: =VLOOKUP($L33,'2026-2027 projections'!$B:$AJ,23,FALSE) -> #N/A | P33: =VLOOKUP($L33,'2026-2027 projections'!$B:$AJ,24,FALSE) -> #N/A | Q33: =VLOOKUP($L33,'2026-2027 projections'!$B:$AJ,25,FALSE) -> #N/A | R33: =VLOOKUP($L33,'2026-2027 projections'!$B:$AJ,26,FALSE) -> #N/A | S33: =VLOOKUP($L33,'2026-2027 projections'!$B:$AJ,27,FALSE) -> #N/A | T33: =VLOOKUP($L33,'2026-2027 projections'!$B:$AJ,28,FALSE) -> #N/A | U33: =VLOOKUP($L33,'2026-2027 projections'!$B:$AJ,29,FALSE) -> #N/A | V33: =VLOOKUP($L33,'2026-2027 projections'!$B:$AJ,30,FALSE) -> #N/A | W33: =VLOOKUP($L33,'2026-2027 projections'!$B:$AJ,31,FALSE) -> #N/A
A34: =A5 -> 0 | B34: =VLOOKUP($A34,'2026-2027 projections'!$B:$AJ,23,FALSE) -> #N/A | C34: =VLOOKUP($A34,'2026-2027 projections'!$B:$AJ,24,FALSE) -> #N/A | D34: =VLOOKUP($A34,'2026-2027 projections'!$B:$AJ,25,FALSE) -> #N/A | E34: =VLOOKUP($A34,'2026-2027 projections'!$B:$AJ,26,FALSE) -> #N/A | F34: =VLOOKUP($A34,'2026-2027 projections'!$B:$AJ,27,FALSE) -> #N/A | G34: =VLOOKUP($A34,'2026-2027 projections'!$B:$AJ,28,FALSE) -> #N/A | H34: =VLOOKUP($A34,'2026-2027 projections'!$B:$AJ,29,FALSE) -> #N/A | I34: =VLOOKUP($A34,'2026-2027 projections'!$B:$AJ,30,FALSE) -> #N/A | J34: =VLOOKUP($A34,'2026-2027 projections'!$B:$AJ,31,FALSE) -> #N/A | L34: Jaylen Brown | M34: =VLOOKUP(L34,'2026-2027 projections'!B:C,2,FALSE) -> 95 | N34: =VLOOKUP(L34,'2026-2027 projections'!B:D,3,FALSE) -> 33 | O34: =VLOOKUP($L34,'2026-2027 projections'!$B:$AJ,23,FALSE) -> 0.17410328 | P34: =VLOOKUP($L34,'2026-2027 projections'!$B:$AJ,24,FALSE) -> -0.52673723 | Q34: =VLOOKUP($L34,'2026-2027 projections'!$B:$AJ,25,FALSE) -> 0.034548399 | R34: =VLOOKUP($L34,'2026-2027 projections'!$B:$AJ,26,FALSE) -> 1.2688088 | S34: =VLOOKUP($L34,'2026-2027 projections'!$B:$AJ,27,FALSE) -> 0.0057968165 | T34: =VLOOKUP($L34,'2026-2027 projections'!$B:$AJ,28,FALSE) -> -0.12869499 | U34: =VLOOKUP($L34,'2026-2027 projections'!$B:$AJ,29,FALSE) -> 0.24532183 | V34: =VLOOKUP($L34,'2026-2027 projections'!$B:$AJ,30,FALSE) -> -0.36262847 | W34: =VLOOKUP($L34,'2026-2027 projections'!$B:$AJ,31,FALSE) -> -0.89278064
A35: =A6 -> 0 | B35: =VLOOKUP($A35,'2026-2027 projections'!$B:$AJ,23,FALSE) -> #N/A | C35: =VLOOKUP($A35,'2026-2027 projections'!$B:$AJ,24,FALSE) -> #N/A | D35: =VLOOKUP($A35,'2026-2027 projections'!$B:$AJ,25,FALSE) -> #N/A | E35: =VLOOKUP($A35,'2026-2027 projections'!$B:$AJ,26,FALSE) -> #N/A | F35: =VLOOKUP($A35,'2026-2027 projections'!$B:$AJ,27,FALSE) -> #N/A | G35: =VLOOKUP($A35,'2026-2027 projections'!$B:$AJ,28,FALSE) -> #N/A | H35: =VLOOKUP($A35,'2026-2027 projections'!$B:$AJ,29,FALSE) -> #N/A | I35: =VLOOKUP($A35,'2026-2027 projections'!$B:$AJ,30,FALSE) -> #N/A | J35: =VLOOKUP($A35,'2026-2027 projections'!$B:$AJ,31,FALSE) -> #N/A | L35: Myles Turner | M35: =VLOOKUP(L35,'2026-2027 projections'!B:C,2,FALSE) -> 88 | N35: =VLOOKUP(L35,'2026-2027 projections'!B:D,3,FALSE) -> 109 | O35: =VLOOKUP($L35,'2026-2027 projections'!$B:$AJ,23,FALSE) -> -0.32855282 | P35: =VLOOKUP($L35,'2026-2027 projections'!$B:$AJ,24,FALSE) -> -0.43719292 | Q35: =VLOOKUP($L35,'2026-2027 projections'!$B:$AJ,25,FALSE) -> 0.45541071 | R35: =VLOOKUP($L35,'2026-2027 projections'!$B:$AJ,26,FALSE) -> -0.49158925 | S35: =VLOOKUP($L35,'2026-2027 projections'!$B:$AJ,27,FALSE) -> 0.047409678 | T35: =VLOOKUP($L35,'2026-2027 projections'!$B:$AJ,28,FALSE) -> -1.1097053 | U35: =VLOOKUP($L35,'2026-2027 projections'!$B:$AJ,29,FALSE) -> -0.92871837 | V35: =VLOOKUP($L35,'2026-2027 projections'!$B:$AJ,30,FALSE) -> 2.2767815 | W35: =VLOOKUP($L35,'2026-2027 projections'!$B:$AJ,31,FALSE) -> 0.60831289
A36: =A7 -> 0 | B36: =VLOOKUP($A36,'2026-2027 projections'!$B:$AJ,23,FALSE) -> #N/A | C36: =VLOOKUP($A36,'2026-2027 projections'!$B:$AJ,24,FALSE) -> #N/A | D36: =VLOOKUP($A36,'2026-2027 projections'!$B:$AJ,25,FALSE) -> #N/A | E36: =VLOOKUP($A36,'2026-2027 projections'!$B:$AJ,26,FALSE) -> #N/A | F36: =VLOOKUP($A36,'2026-2027 projections'!$B:$AJ,27,FALSE) -> #N/A | G36: =VLOOKUP($A36,'2026-2027 projections'!$B:$AJ,28,FALSE) -> #N/A | H36: =VLOOKUP($A36,'2026-2027 projections'!$B:$AJ,29,FALSE) -> #N/A | I36: =VLOOKUP($A36,'2026-2027 projections'!$B:$AJ,30,FALSE) -> #N/A | J36: =VLOOKUP($A36,'2026-2027 projections'!$B:$AJ,31,FALSE) -> #N/A | L36: Derrick White | M36: =VLOOKUP(L36,'2026-2027 projections'!B:C,2,FALSE) -> 29 | N36: =VLOOKUP(L36,'2026-2027 projections'!B:D,3,FALSE) -> 36 | O36: =VLOOKUP($L36,'2026-2027 projections'!$B:$AJ,23,FALSE) -> -1.5913167 | P36: =VLOOKUP($L36,'2026-2027 projections'!$B:$AJ,24,FALSE) -> 0.66820906 | Q36: =VLOOKUP($L36,'2026-2027 projections'!$B:$AJ,25,FALSE) -> 1.5075665 | R36: =VLOOKUP($L36,'2026-2027 projections'!$B:$AJ,26,FALSE) -> 0.11413911 | S36: =VLOOKUP($L36,'2026-2027 projections'!$B:$AJ,27,FALSE) -> -0.49355752 | T36: =VLOOKUP($L36,'2026-2027 projections'!$B:$AJ,28,FALSE) -> 0.74905111 | U36: =VLOOKUP($L36,'2026-2027 projections'!$B:$AJ,29,FALSE) -> 0.24532183 | V36: =VLOOKUP($L36,'2026-2027 projections'!$B:$AJ,30,FALSE) -> 1.0585923 | W36: =VLOOKUP($L36,'2026-2027 projections'!$B:$AJ,31,FALSE) -> 0.19892375
A37: =A8 -> 0 | B37: =VLOOKUP($A37,'2026-2027 projections'!$B:$AJ,23,FALSE) -> #N/A | C37: =VLOOKUP($A37,'2026-2027 projections'!$B:$AJ,24,FALSE) -> #N/A | D37: =VLOOKUP($A37,'2026-2027 projections'!$B:$AJ,25,FALSE) -> #N/A | E37: =VLOOKUP($A37,'2026-2027 projections'!$B:$AJ,26,FALSE) -> #N/A | F37: =VLOOKUP($A37,'2026-2027 projections'!$B:$AJ,27,FALSE) -> #N/A | G37: =VLOOKUP($A37,'2026-2027 projections'!$B:$AJ,28,FALSE) -> #N/A | H37: =VLOOKUP($A37,'2026-2027 projections'!$B:$AJ,29,FALSE) -> #N/A | I37: =VLOOKUP($A37,'2026-2027 projections'!$B:$AJ,30,FALSE) -> #N/A | J37: =VLOOKUP($A37,'2026-2027 projections'!$B:$AJ,31,FALSE) -> #N/A | L37: Pascal Siakam | M37: =VLOOKUP(L37,'2026-2027 projections'!B:C,2,FALSE) -> 47 | N37: =VLOOKUP(L37,'2026-2027 projections'!B:D,3,FALSE) -> 98 | O37: =VLOOKUP($L37,'2026-2027 projections'!$B:$AJ,23,FALSE) -> 0.65669969 | P37: =VLOOKUP($L37,'2026-2027 projections'!$B:$AJ,24,FALSE) -> -1.2308764 | Q37: =VLOOKUP($L37,'2026-2027 projections'!$B:$AJ,25,FALSE) -> 0.13976398 | R37: =VLOOKUP($L37,'2026-2027 projections'!$B:$AJ,26,FALSE) -> 1.3823829 | S37: =VLOOKUP($L37,'2026-2027 projections'!$B:$AJ,27,FALSE) -> 0.62998974 | T37: =VLOOKUP($L37,'2026-2027 projections'!$B:$AJ,28,FALSE) -> 0.0778335 | U37: =VLOOKUP($L37,'2026-2027 projections'!$B:$AJ,29,FALSE) -> 0.24532183 | V37: =VLOOKUP($L37,'2026-2027 projections'!$B:$AJ,30,FALSE) -> -0.36262847 | W37: =VLOOKUP($L37,'2026-2027 projections'!$B:$AJ,31,FALSE) -> -0.07400235
B38: =VLOOKUP($A38,'2026-2027 projections'!$B:$AJ,23,FALSE) -> #N/A | C38: =VLOOKUP($A38,'2026-2027 projections'!$B:$AJ,24,FALSE) -> #N/A | D38: =VLOOKUP($A38,'2026-2027 projections'!$B:$AJ,25,FALSE) -> #N/A | E38: =VLOOKUP($A38,'2026-2027 projections'!$B:$AJ,26,FALSE) -> #N/A | F38: =VLOOKUP($A38,'2026-2027 projections'!$B:$AJ,27,FALSE) -> #N/A | G38: =VLOOKUP($A38,'2026-2027 projections'!$B:$AJ,28,FALSE) -> #N/A | H38: =VLOOKUP($A38,'2026-2027 projections'!$B:$AJ,29,FALSE) -> #N/A | I38: =VLOOKUP($A38,'2026-2027 projections'!$B:$AJ,30,FALSE) -> #N/A | J38: =VLOOKUP($A38,'2026-2027 projections'!$B:$AJ,31,FALSE) -> #N/A | L38: Rudy Gobert | M38: =VLOOKUP(L38,'2026-2027 projections'!B:C,2,FALSE) -> 69 | N38: =VLOOKUP(L38,'2026-2027 projections'!B:D,3,FALSE) -> 59 | O38: =VLOOKUP($L38,'2026-2027 projections'!$B:$AJ,23,FALSE) -> 2.3309588 | P38: =VLOOKUP($L38,'2026-2027 projections'!$B:$AJ,24,FALSE) -> -2 | Q38: =VLOOKUP($L38,'2026-2027 projections'!$B:$AJ,25,FALSE) -> -1.7541164 | R38: =VLOOKUP($L38,'2026-2027 projections'!$B:$AJ,26,FALSE) -> -0.87016948 | S38: =VLOOKUP($L38,'2026-2027 projections'!$B:$AJ,27,FALSE) -> 2.2528913 | T38: =VLOOKUP($L38,'2026-2027 projections'!$B:$AJ,28,FALSE) -> -1.0064411 | U38: =VLOOKUP($L38,'2026-2027 projections'!$B:$AJ,29,FALSE) -> -0.63520832 | V38: =VLOOKUP($L38,'2026-2027 projections'!$B:$AJ,30,FALSE) -> 1.6676869 | W38: =VLOOKUP($L38,'2026-2027 projections'!$B:$AJ,31,FALSE) -> 0.74477594
A39: =A10 -> 0 | B39: =VLOOKUP($A39,'2026-2027 projections'!$B:$AJ,23,FALSE) -> #N/A | C39: =VLOOKUP($A39,'2026-2027 projections'!$B:$AJ,24,FALSE) -> #N/A | D39: =VLOOKUP($A39,'2026-2027 projections'!$B:$AJ,25,FALSE) -> #N/A | E39: =VLOOKUP($A39,'2026-2027 projections'!$B:$AJ,26,FALSE) -> #N/A | F39: =VLOOKUP($A39,'2026-2027 projections'!$B:$AJ,27,FALSE) -> #N/A | G39: =VLOOKUP($A39,'2026-2027 projections'!$B:$AJ,28,FALSE) -> #N/A | H39: =VLOOKUP($A39,'2026-2027 projections'!$B:$AJ,29,FALSE) -> #N/A | I39: =VLOOKUP($A39,'2026-2027 projections'!$B:$AJ,30,FALSE) -> #N/A | J39: =VLOOKUP($A39,'2026-2027 projections'!$B:$AJ,31,FALSE) -> #N/A | L39: Demar Derozan | M39: =VLOOKUP(L39,'2026-2027 projections'!B:C,2,FALSE) -> 123 | N39: =VLOOKUP(L39,'2026-2027 projections'!B:D,3,FALSE) -> 80 | O39: =VLOOKUP($L39,'2026-2027 projections'!$B:$AJ,23,FALSE) -> 0.27480759 | P39: =VLOOKUP($L39,'2026-2027 projections'!$B:$AJ,24,FALSE) -> 1.0512256 | Q39: =VLOOKUP($L39,'2026-2027 projections'!$B:$AJ,25,FALSE) -> -0.80717623 | R39: =VLOOKUP($L39,'2026-2027 projections'!$B:$AJ,26,FALSE) -> 0.057352079 | S39: =VLOOKUP($L39,'2026-2027 projections'!$B:$AJ,27,FALSE) -> -1.242589 | T39: =VLOOKUP($L39,'2026-2027 projections'!$B:$AJ,28,FALSE) -> -0.69664835 | U39: =VLOOKUP($L39,'2026-2027 projections'!$B:$AJ,29,FALSE) -> -0.34169827 | V39: =VLOOKUP($L39,'2026-2027 projections'!$B:$AJ,30,FALSE) -> -0.56566001 | W39: =VLOOKUP($L39,'2026-2027 projections'!$B:$AJ,31,FALSE) -> 1.1541651
A40: =A11 -> 0 | B40: =VLOOKUP($A40,'2026-2027 projections'!$B:$AJ,23,FALSE) -> #N/A | C40: =VLOOKUP($A40,'2026-2027 projections'!$B:$AJ,24,FALSE) -> #N/A | D40: =VLOOKUP($A40,'2026-2027 projections'!$B:$AJ,25,FALSE) -> #N/A | E40: =VLOOKUP($A40,'2026-2027 projections'!$B:$AJ,26,FALSE) -> #N/A | F40: =VLOOKUP($A40,'2026-2027 projections'!$B:$AJ,27,FALSE) -> #N/A | G40: =VLOOKUP($A40,'2026-2027 projections'!$B:$AJ,28,FALSE) -> #N/A | H40: =VLOOKUP($A40,'2026-2027 projections'!$B:$AJ,29,FALSE) -> #N/A | I40: =VLOOKUP($A40,'2026-2027 projections'!$B:$AJ,30,FALSE) -> #N/A | J40: =VLOOKUP($A40,'2026-2027 projections'!$B:$AJ,31,FALSE) -> #N/A | L40: Nikola Vucevic | M40: =VLOOKUP(L40,'2026-2027 projections'!B:C,2,FALSE) -> 168 | N40: =VLOOKUP(L40,'2026-2027 projections'!B:D,3,FALSE) -> 75 | O40: =VLOOKUP($L40,'2026-2027 projections'!$B:$AJ,23,FALSE) -> 0.19824535 | P40: =VLOOKUP($L40,'2026-2027 projections'!$B:$AJ,24,FALSE) -> 0.16028022 | Q40: =VLOOKUP($L40,'2026-2027 projections'!$B:$AJ,25,FALSE) -> -0.59674507 | R40: =VLOOKUP($L40,'2026-2027 projections'!$B:$AJ,26,FALSE) -> -0.92695651 | S40: =VLOOKUP($L40,'2026-2027 projections'!$B:$AJ,27,FALSE) -> 0.25547398 | T40: =VLOOKUP($L40,'2026-2027 projections'!$B:$AJ,28,FALSE) -> -0.69664835 | U40: =VLOOKUP($L40,'2026-2027 projections'!$B:$AJ,29,FALSE) -> -1.5157385 | V40: =VLOOKUP($L40,'2026-2027 projections'!$B:$AJ,30,FALSE) -> -0.36262847 | W40: =VLOOKUP($L40,'2026-2027 projections'!$B:$AJ,31,FALSE) -> 1.1541651
A41: =A12 -> 0 | B41: =VLOOKUP($A41,'2026-2027 projections'!$B:$AJ,23,FALSE) -> #N/A | C41: =VLOOKUP($A41,'2026-2027 projections'!$B:$AJ,24,FALSE) -> #N/A | D41: =VLOOKUP($A41,'2026-2027 projections'!$B:$AJ,25,FALSE) -> #N/A | E41: =VLOOKUP($A41,'2026-2027 projections'!$B:$AJ,26,FALSE) -> #N/A | F41: =VLOOKUP($A41,'2026-2027 projections'!$B:$AJ,27,FALSE) -> #N/A | G41: =VLOOKUP($A41,'2026-2027 projections'!$B:$AJ,28,FALSE) -> #N/A | H41: =VLOOKUP($A41,'2026-2027 projections'!$B:$AJ,29,FALSE) -> #N/A | I41: =VLOOKUP($A41,'2026-2027 projections'!$B:$AJ,30,FALSE) -> #N/A | J41: =VLOOKUP($A41,'2026-2027 projections'!$B:$AJ,31,FALSE) -> #N/A | L41: Jalen Duren | M41: =VLOOKUP(L41,'2026-2027 projections'!B:C,2,FALSE) -> 31 | N41: =VLOOKUP(L41,'2026-2027 projections'!B:D,3,FALSE) -> 40 | O41: =VLOOKUP($L41,'2026-2027 projections'!$B:$AJ,23,FALSE) -> 3.1949877 | P41: =VLOOKUP($L41,'2026-2027 projections'!$B:$AJ,24,FALSE) -> -0.81192971 | Q41: =VLOOKUP($L41,'2026-2027 projections'!$B:$AJ,25,FALSE) -> -1.7541164 | R41: =VLOOKUP($L41,'2026-2027 projections'!$B:$AJ,26,FALSE) -> 0.34128725 | S41: =VLOOKUP($L41,'2026-2027 projections'!$B:$AJ,27,FALSE) -> 2.2528913 | T41: =VLOOKUP($L41,'2026-2027 projections'!$B:$AJ,28,FALSE) -> -0.59338411 | U41: =VLOOKUP($L41,'2026-2027 projections'!$B:$AJ,29,FALSE) -> -0.63520832 | V41: =VLOOKUP($L41,'2026-2027 projections'!$B:$AJ,30,FALSE) -> 0.44949769 | W41: =VLOOKUP($L41,'2026-2027 projections'!$B:$AJ,31,FALSE) -> -0.07400235
...

Sheet 2026-2027 means
A1: FGM | B1: FGA | C1: FTM | D1: FTA | E1: FG% | F1: FT% | G1: 3PM | H1: PTS | I1: TREB | J1: AST | K1: STL | L1: BLK | M1: TO | N1: FGM_stdev | O1: FGA_stdev | P1: FTM_stdev | Q1: FTA_stdev | R1: FG%_stdev | S1: FT%_stdev | T1: 3PM_stdev | U1: PTS_stdev | V1: TREB_stdev | W1: AST_stdev | X1: STL_stdev | Y1: BLK_stdev | Z1: TO_stdev
A2: =AVERAGE('2026-2027 projections'!R:R) -> 5.7721393 | B2: =AVERAGE('2026-2027 projections'!S:S) -> 11.958706 | C2: =AVERAGE('2026-2027 projections'!U:U) -> 2.6900498 | D2: =AVERAGE('2026-2027 projections'!V:V) -> 3.3840796 | E2: =A2/B2 -> 0.48267255 | F2: =C2/D2 -> 0.79491326 | G2: =AVERAGE('2026-2027 projections'!J:J) -> 1.6671642 | H2: =AVERAGE('2026-2027 projections'!K:K) -> 15.897015 | I2: =AVERAGE('2026-2027 projections'!L:L) -> 5.6860697 | J2: =AVERAGE('2026-2027 projections'!M:M) -> 3.6492537 | K2: =AVERAGE('2026-2027 projections'!N:N) -> 1.0164179 | L2: =AVERAGE('2026-2027 projections'!O:O) -> 0.67860697 | M2: =AVERAGE('2026-2027 projections'!P:P) -> 1.8457711 | N2: =STDEV('2026-2027 projections'!R:R) -> 1.7948593 | O2: =STDEV('2026-2027 projections'!S:S) -> 3.857115 | P2: =STDEV('2026-2027 projections'!U:U) -> 1.4813509 | Q2: =STDEV('2026-2027 projections'!V:V) -> 1.7994569 | R2: 0.02271 | S2: 0.085 | T2: =STDEV('2026-2027 projections'!J:J) -> 0.9504296 | U2: =STDEV('2026-2027 projections'!K:K) -> 5.2828961 | V2: =STDEV('2026-2027 projections'!L:L) -> 2.4031032 | W2: =STDEV('2026-2027 projections'!M:M) -> 1.9367788 | X2: =STDEV('2026-2027 projections'!N:N) -> 0.34070384 | Y2: =STDEV('2026-2027 projections'!O:O) -> 0.49253431 | Z2: =STDEV('2026-2027 projections'!P:P) -> 0.7327991

Sheet 2026-2027 projections
A1: Projected Rank | B1: PLAYER | C1: Projected Rank | D1: LY Rank | E1: ADP | F1: Delta | G1: Do not draft | H1: FG% | I1: FT% | J1: 3PM | K1: PTS | L1: TREB | M1: AST | N1: STL | O1: BLK | P1: TO | Q1: TOTAL | R1: FGM | S1: FGA | T1: FGpct | U1: FTM | V1: FTA | W1: FTpct | X1: FG%_stdev | Y1: FT%_stdev | Z1: 3PM_stdev | AA1: PTS_stdev | AB1: TREB_stdev | AC1: AST_stdev | AD1: STL_stdev | AE1: BLK_stdev | AF1: TO_stdev | AG1: Plus_categories | AH1: Negative Categories | AI1: Percentage | AJ1: Stregnths | AK1: Weakness | AL1: Excellent | AM1: Good | AN1: Above Average | AO1: Below Average | AP1: LY Rank | AQ1: MYTOTAL | AR1: MYRANK
A2: =C2 -> 1 | B2: Nikola Jokic | C2: =AR2 -> 1 | D2: =AP2 -> 1 | E2: =VLOOKUP(B2,'2026-2027 adp'!A:C,3,FALSE) -> 1.5 | F2: =E2-A2 -> 0.5 | H2: 0.579(10.9/18.9) | I2: 0.808(4.9/6.0) | J2: 1.8 | K2: 28.4 | L2: 12.7 | M2: 10.4 | N2: 1.6 | O2: 0.7 | P2: 3.5 | Q2: 15.89 | R2: 10.5 | S2: 18.3 | T2: =R2/S2 -> 0.57377049 | U2: 5.6 | V2: 6.8 | W2: =U2/V2 -> 0.82352941 | X2: =IF(((T2 - '2026-2027 means'!E$2) / '2026-2027 means'!R$2) * (S2 / '2026-2027 means'!B$2) / 2 < -2, -2, ((T2 - '2026-2027 means'!E$2) / '2026-2027 means'!R$2) * (S2 / '2026-2027 means'!B$2) / 2) -> 3.0692222 | Y2: =IF(((W2 - '2026-2027 means'!F$2) / '2026-2027 means'!S$2) * (V2 / '2026-2027 means'!D$2) < -2, -2, ((W2 - '2026-2027 means'!F$2) / '2026-2027 means'!S$2) * (V2 / '2026-2027 means'!D$2)) -> 0.67648884 | Z2: =(J2-'2026-2027 means'!G$2)/'2026-2027 means'!T$2 -> 0.13976398 | AA2: =(K2-'2026-2027 means'!H$2)/'2026-2027 means'!U$2 -> 2.3666915 | AB2: =(L2-'2026-2027 means'!I$2)/'2026-2027 means'!V$2 -> 2.9186971 | AC2: =(M2-'2026-2027 means'!J$2)/'2026-2027 means'!W$2 -> 3.4855537 | AD2: =(N2-'2026-2027 means'!K$2)/'2026-2027 means'!X$2 -> 1.7128721 | AE2: =(O2-'2026-2027 means'!L$2)/'2026-2027 means'!Y$2 -> 0.043434608 | AF2: =IF(((P2 - '2026-2027 means'!M$2) / '2026-2027 means'!Z$2 * -1) < -2, -2, (P2 - '2026-2027 means'!M$2) / '2026-2027 means'!Z$2 * -1) -> -2 | AG2: =IF(((Q2 - '2026-2027 means'!N$2) / '2026-2027 means'!AA$2 * -1) < -2, -2, (Q2 - '2026-2027 means'!N$2) / '2026-2027 means'!AA$2 * -1) -> #DIV/0! | AH2: =IF(((R2 - '2026-2027 means'!O$2) / '2026-2027 means'!AB$2 * -1) < -2, -2, (R2 - '2026-2027 means'!O$2) / '2026-2027 means'!AB$2 * -1) -> #DIV/0! | AI2: =IF(((S2 - '2026-2027 means'!P$2) / '2026-2027 means'!AC$2 * -1) < -2, -2, (S2 - '2026-2027 means'!P$2) / '2026-2027 means'!AC$2 * -1) -> #DIV/0! | AJ2: =IF(((T2 - '2026-2027 means'!Q$2) / '2026-2027 means'!AD$2 * -1) < -2, -2, (T2 - '2026-2027 means'!Q$2) / '2026-2027 means'!AD$2 * -1) -> #DIV/0! | AK2: =IF(((U2 - '2026-2027 means'!R$2) / '2026-2027 means'!AE$2 * -1) < -2, -2, (U2 - '2026-2027 means'!R$2) / '2026-2027 means'!AE$2 * -1) -> #DIV/0! | AL2: =IF(((V2 - '2026-2027 means'!S$2) / '2026-2027 means'!AF$2 * -1) < -2, -2, (V2 - '2026-2027 means'!S$2) / '2026-2027 means'!AF$2 * -1) -> #DIV/0! | AM2: =IF(((W2 - '2026-2027 means'!T$2) / '2026-2027 means'!AG$2 * -1) < -2, -2, (W2 - '2026-2027 means'!T$2) / '2026-2027 means'!AG$2 * -1) -> #DIV/0! | ... AO2: =IF(((Y2 - '2026-2027 means'!V$2) / '2026-2027 means'!AI$2 * -1) < -2, -2, (Y2 - '2026-2027 means'!V$2) / '2026-2027 means'!AI$2 * -1) -> #DIV/0! | AP2: =VLOOKUP(B2,'2025-2026 actuals'!B:Q,16,FALSE) -> 1 | AQ2: =SUM(X2:AF2) -> 12.412724 | AR2: =RANK(AQ2,AQ:AQ) -> 1
